Workbook

Sheet Read Me
A1: Legend Player Attribute Pack — First-Pass Draft for Review
A3: What this is
A4: Second-pass, directly-researched 1-20 attribute estimates for the legend players on the 'Legend Attributes' sheet, covering the exact 34 stat fields the live match engine (web/static/tactic_board.js) reads today — not the compressed FM-style category taxonomy from fm_style_player_datapack.xlsx (Finishing/Passing/Tackling/etc). Each attribute maps to ONE specific engine stat field, so the conversion to a per-90 number is a direct, transparent linear scale rather than a multi-stat blend.
A6: What changed in this revision
A7: The user removed several players, added Messi and Ronaldo, and flagged that the first pass leaned too heavily on shared role-archetype templates — most players within a position looked statistically similar. This pass individualizes every player against specific, well-known career signatures instead (e.g. among the 4 CBs: Piqué is the ball-playing passer who also drew more cards, Terry the all-round leader, Vidić the purest destroyer with the least polished passing, Thiago Silva the elite reader with the highest interceptions and fewest cards) and pushes each player's OWN profile further across the 1-20 range between their genuine strengths and weaknesses, rather than clustering every attribute near the role's center.
A9: How the conversion works
A10: The 'Conversion Range' sheet defines a realistic (min, max) per-90 range for each field, sourced from the same reference ceilings the engine already uses (formation_fit.py's STAT_CAPS) plus general knowledge of realistic top-5-league distributions. An attribute of 1 maps to the field's min, 20 maps to its max, and values in between are a straight linear interpolation. The 'Converted Per-90 Preview' sheet computes this live via formula — edit any attribute on the 'Legend Attributes' sheet and the preview updates.
A12: Attribute 0 = not applicable
A13: A handful of cells use 0 instead of 1-20 -- a deliberate sentinel for a field that genuinely doesn't apply (an outfield player's saves90/goals_prevented90/clean_sheet_pct, a goalkeeper's xg90/shots90/goals90/etc). These always convert to exactly 0, not the field's normal min. Every other cell is a real 1-20 judgment.
A15: Inverted fields
A16: Five fields (big_chances_missed90, possession_lost90, goals_conceded90, yellow_cards90, red_cards90) are marked inverted on the Conversion Range sheet: for these, a HIGH attribute (near 20, meaning 'good') maps to a LOW raw stat, since fewer cards/turnovers/wasted chances is the better outcome. This keeps '20 = best' consistent across every attribute, unlike a raw stat where higher isn't always better.
A18: Status — NOT YET WIRED INTO THE ENGINE
... A24: Sheets: Conversion Range | Legend Attributes (edit here) | Converted Per-90 Preview (read-only, live formulas)

Sheet Conversion Range
A1: Stat field | B1: Label | C1: Min (attr=1) | D1: Max (attr=20) | E1: Inverted? | F1: Note
A2: xg90 | B2: xG per 90 | C2: 0.02 | D2: 0.85 | E2: 0
A3: npxg90 | B3: Non-pen xG per 90 | C3: 0.02 | D3: 0.75 | E3: 0
A4: xa90 | B4: xA per 90 | C4: 0.01 | D4: 0.55 | E4: 0
A5: shots90 | B5: Shots per 90 | C5: 0.15 | D5: 4 | E5: 0 | F5: capped at formation_fit.py STAT_CAPS (4.0)
A6: shots_on_target90 | B6: Shots on target per 90 | C6: 0.08 | D6: 2.3 | E6: 0
A7: goals90 | B7: Goals per 90 | C7: 0 | D7: 1 | E7: 0
A8: key_passes90 | B8: Key passes per 90 | C8: 0.1 | D8: 2.6 | E8: 0
A9: tackles90 | B9: Tackles per 90 | C9: 0.2 | D9: 3.3 | E9: 0 | F9: capped near STAT_CAPS (3.5)
A10: interceptions90 | B10: Interceptions per 90 | C10: 0.1 | D10: 2.3 | E10: 0 | F10: capped near STAT_CAPS (2.5)
A11: clearances90 | B11: Clearances per 90 | C11: 0 | D11: 6.2 | E11: 0 | F11: capped near STAT_CAPS (6.0)
A12: blocks90 | B12: Blocks per 90 | C12: 0 | D12: 1.6 | E12: 0
A13: ball_recoveries90 | B13: Ball recoveries per 90 | C13: 2 | D13: 9.5 | E13: 0
A14: dribbles90 | B14: Dribbles per 90 | C14: 0.1 | D14: 3.2 | E14: 0 | F14: capped near STAT_CAPS (3.0)
A15: dribble_pct | B15: Dribble success % | C15: 30 | D15: 85 | E15: 0
A16: duels_won_pct | B16: Duels won % | C16: 35 | D16: 68 | E16: 0
A17: pass_pct | B17: Pass completion % | C17: 55 | D17: 95 | E17: 0
A18: long_balls90 | B18: Long balls per 90 | C18: 0.3 | D18: 8.5 | E18: 0
A19: long_ball_pct | B19: Long ball accuracy % | C19: 25 | D19: 68 | E19: 0
A20: aerials_won90 | B20: Aerials won per 90 | C20: 0.3 | D20: 5.5 | E20: 0
A21: aerials_won_pct | B21: Aerial win % | C21: 30 | D21: 75 | E21: 0
A22: assists90 | B22: Assists per 90 | C22: 0 | D22: 0.5 | E22: 0
A23: big_chances_created90 | B23: Big chances created per 90 | C23: 0 | D23: 1.1 | E23: 0 | F23: capped near STAT_CAPS (1.2)
A24: big_chances_missed90 | B24: Big chances missed per 90 | C24: 0 | D24: 0.9 | E24: 1 | F24: INVERTED -- 20 = clinical/rarely wastes
A25: possession_lost90 | B25: Possession lost per 90 | C25: 3.5 | D25: 16 | E25: 1 | F25: INVERTED -- 20 = very secure on the ball
A26: penalty_goals90 | B26: Penalty goals per 90 | C26: 0 | D26: 0.35 | E26: 0
A27: xg_chain90 | B27: xG chain per 90 | C27: 0.05 | D27: 0.95 | E27: 0 | F27: involvement in shot-ending possessions
A28: xg_buildup90 | B28: xG buildup per 90 | C28: 0.03 | D28: 0.55 | E28: 0 | F28: involvement excluding own shots/assists
A29: saves90 | B29: Saves per 90 (GK) | C29: 1 | D29: 4.5 | E29: 0 | F29: capped at STAT_CAPS (4.5); ~0 for outfield
A30: goals_prevented90 | B30: Goals prevented per 90 (GK) | C30: -0.3 | D30: 0.7 | E30: 0 | F30: post-shot xG minus goals conceded; can be negative
A31: clean_sheet_pct | B31: Clean sheet % (GK) | C31: 5 | D31: 55 | E31: 0
A32: goals_conceded90 | B32: Team goals conceded per 90 | C32: 0.5 | D32: 2 | E32: 1 | F32: INVERTED -- 20 = played for a stingy defense
A33: yellow_cards90 | B33: Yellow cards per 90 | C33: 0.02 | D33: 0.45 | E33: 1 | F33: INVERTED -- 20 = very disciplined
A34: red_cards90 | B34: Red cards per 90 | C34: 0 | D34: 0.12 | E34: 1 | F34: INVERTED -- 20 = very disciplined
A35: rating | B35: Average match rating | C35: 6.4 | D35: 8.2 | E35: 0 | F35: realistic top-tier career-peak range

Sheet Legend Attributes
A1: Player | B1: Position | C1: xg90 | D1: npxg90 | E1: xa90 | F1: shots90 | G1: shots_on_target90 | H1: goals90 | I1: key_passes90 | J1: tackles90 | K1: interceptions90 | L1: clearances90 | M1: blocks90 | N1: ball_recoveries90 | O1: dribbles90 | P1: dribble_pct | Q1: duels_won_pct | R1: pass_pct | S1: long_balls90 | T1: long_ball_pct | U1: aerials_won90 | V1: aerials_won_pct | W1: assists90 | X1: big_chances_created90 | Y1: big_chances_missed90 | Z1: possession_lost90 | AA1: penalty_goals90 | AB1: xg_chain90 | AC1: xg_buildup90 | AD1: saves90 | AE1: goals_prevented90 | AF1: clean_sheet_pct | AG1: goals_conceded90 | AH1: yellow_cards90 | AI1: red_cards90 | AJ1: rating
A2: Eden Hazard | B2: W | C2: 14 | D2: 14 | E2: 17 | F2: 12 | G2: 12 | H2: 14 | I2: 16 | J2: 6 | K2: 5 | L2: 1 | M2: 3 | N2: 7 | O2: 19 | P2: 17 | Q2: 13 | R2: 15 | S2: 4 | T2: 9 | U2: 5 | V2: 9 | W2: 17 | X2: 16 | Y2: 13 | Z2: 12 | AA2: 12 | AB2: 17 | AC2: 16 | AD2: 0 | AE2: 0 | AF2: 0 | AG2: 15 | AH2: 15 | AI2: 17 | AJ2: 17
A3: Luis Suárez | B3: ST | C3: 17 | D3: 16 | E3: 14 | F3: 16 | G3: 15 | H3: 17 | I3: 12 | J3: 7 | K3: 6 | L3: 2 | M3: 3 | N3: 9 | O3: 15 | P3: 15 | Q3: 15 | R3: 13 | S3: 4 | T3: 8 | U3: 11 | V3: 12 | W3: 14 | X3: 12 | Y3: 13 | Z3: 10 | AA3: 14 | AB3: 16 | AC3: 14 | AD3: 0 | AE3: 0 | AF3: 0 | AG3: 14 | AH3: 5 | AI3: 4 | AJ3: 17
A4: Sergio Agüero | B4: ST | C4: 16 | D4: 16 | E4: 9 | F4: 15 | G4: 15 | H4: 18 | I4: 7 | J4: 3 | K4: 3 | L4: 1 | M4: 1 | N4: 5 | O4: 13 | P4: 15 | Q4: 10 | R4: 12 | S4: 2 | T4: 6 | U4: 7 | V4: 9 | W4: 8 | X4: 8 | Y4: 16 | Z4: 13 | AA4: 16 | AB4: 14 | AC4: 10 | AD4: 0 | AE4: 0 | AF4: 0 | AG4: 12 | AH4: 15 | AI4: 17 | AJ4: 17
A5: Andrés Iniesta | B5: CM | C5: 7 | D5: 7 | E5: 16 | F5: 5 | G5: 5 | H5: 6 | I5: 17 | J5: 8 | K5: 10 | L5: 2 | M5: 3 | N5: 12 | O5: 18 | P5: 19 | Q5: 10 | R5: 20 | S5: 9 | T5: 14 | U5: 3 | V5: 6 | W5: 16 | X5: 15 | Y5: 15 | Z5: 18 | AA5: 5 | AB5: 18 | AC5: 18 | AD5: 0 | AE5: 0 | AF5: 0 | AG5: 17 | AH5: 15 | AI5: 17 | AJ5: 18
A6: Arjen Robben | B6: W | C6: 16 | D6: 16 | E6: 11 | F6: 15 | G6: 14 | H6: 16 | I6: 10 | J6: 5 | K6: 4 | L6: 1 | M6: 2 | N6: 6 | O6: 15 | P6: 13 | Q6: 12 | R6: 13 | S6: 3 | T6: 8 | U6: 4 | V6: 8 | W6: 11 | X6: 10 | Y6: 11 | Z6: 11 | AA6: 6 | AB6: 14 | AC6: 11 | AD6: 0 | AE6: 0 | AF6: 0 | AG6: 15 | AH6: 15 | AI6: 17 | AJ6: 16
A7: Neymar | B7: W | C7: 15 | D7: 15 | E7: 15 | F7: 14 | G7: 13 | H7: 15 | I7: 14 | J7: 4 | K7: 4 | L7: 1 | M7: 2 | N7: 6 | O7: 20 | P7: 17 | Q7: 12 | R7: 14 | S7: 4 | T7: 9 | U7: 4 | V7: 8 | W7: 15 | X7: 14 | Y7: 12 | Z7: 9 | AA7: 13 | AB7: 18 | AC7: 13 | AD7: 0 | AE7: 0 | AF7: 0 | AG7: 15 | AH7: 10 | AI7: 8 | AJ7: 18
A8: Gareth Bale | B8: W | C8: 16 | D8: 16 | E8: 10 | F8: 16 | G8: 15 | H8: 17 | I8: 8 | J8: 5 | K8: 5 | L8: 1 | M8: 2 | N8: 6 | O8: 12 | P8: 12 | Q8: 14 | R8: 12 | S8: 4 | T8: 9 | U8: 11 | V8: 12 | W8: 9 | X8: 8 | Y8: 12 | Z8: 11 | AA8: 9 | AB8: 13 | AC8: 10 | AD8: 0 | AE8: 0 | AF8: 0 | AG8: 16 | AH8: 14 | AI8: 16 | AJ8: 16
A9: Frank Lampard | B9: CM | C9: 15 | D9: 15 | E9: 11 | F9: 15 | G9: 14 | H9: 16 | I9: 11 | J9: 9 | K9: 9 | L9: 4 | M9: 4 | N9: 11 | O9: 7 | P9: 10 | Q9: 11 | R9: 15 | S9: 7 | T9: 12 | U9: 10 | V9: 11 | W9: 10 | X9: 13 | Y9: 13 | Z9: 13 | AA9: 18 | AB9: 13 | AC9: 15 | AD9: 0 | AE9: 0 | AF9: 0 | AG9: 13 | AH9: 13 | AI9: 15 | AJ9: 19
A10: Steven Gerrard | B10: CM | C10: 14 | D10: 13 | E10: 13 | F10: 14 | G10: 13 | H10: 13 | I10: 13 | J10: 12 | K10: 12 | L10: 6 | M10: 5 | N10: 14 | O10: 9 | P10: 11 | Q10: 14 | R10: 14 | S10: 11 | T10: 14 | U10: 10 | V10: 11 | W10: 12 | X10: 14 | Y10: 10 | Z10: 11 | AA10: 12 | AB10: 15 | AC10: 15 | AD10: 0 | AE10: 0 | AF10: 0 | AG10: 10 | AH10: 9 | AI10: 10 | AJ10: 17
A11: Andrea Pirlo | B11: DM | C11: 4 | D11: 4 | E11: 14 | F11: 6 | G11: 5 | H11: 5 | I11: 16 | J11: 7 | K11: 11 | L11: 3 | M11: 3 | N11: 13 | O11: 7 | P11: 14 | Q11: 8 | R11: 20 | S11: 19 | T11: 19 | U11: 4 | V11: 7 | W11: 12 | X11: 14 | Y11: 15 | Z11: 18 | AA11: 8 | AB11: 17 | AC11: 19 | AD11: 0 | AE11: 0 | AF11: 0 | AG11: 15 | AH11: 14 | AI11: 17 | AJ11: 17
A12: Yaya Touré | B12: CM | C12: 13 | D12: 12 | E12: 9 | F12: 12 | G12: 10 | H12: 12 | I12: 9 | J12: 10 | K12: 9 | L12: 5 | M12: 4 | N12: 12 | O12: 12 | P12: 13 | Q12: 16 | R12: 13 | S12: 7 | T12: 10 | U12: 12 | V12: 13 | W12: 8 | X12: 7 | Y12: 10 | Z12: 10 | AA12: 8 | AB12: 12 | AC12: 12 | AD12: 0 | AE12: 0 | AF12: 0 | AG12: 13 | AH12: 10 | AI12: 11 | AJ12: 16
A13: Cesc Fàbregas | B13: CM | C13: 9 | D13: 9 | E13: 18 | F13: 9 | G13: 7 | H13: 9 | I13: 19 | J13: 7 | K13: 8 | L13: 2 | M13: 3 | N13: 10 | O13: 10 | P13: 12 | Q13: 8 | R13: 16 | S13: 11 | T13: 15 | U13: 4 | V13: 7 | W13: 18 | X13: 18 | Y13: 12 | Z13: 12 | AA13: 6 | AB13: 17 | AC13: 16 | AD13: 0 | AE13: 0 | AF13: 0 | AG13: 11 | AH13: 13 | AI13: 15 | AJ13: 16
... A38: James Milner | B38: CM | C38: 7 | D38: 7 | E38: 13 | F38: 7 | G38: 6 | H38: 3 | I38: 11 | J38: 13 | K38: 9 | L38: 6 | M38: 6 | N38: 13 | O38: 6 | P38: 11 | Q38: 11 | R38: 14 | S38: 9 | T38: 12 | U38: 6 | V38: 8 | W38: 6 | X38: 10 | Y38: 12 | Z38: 14 | AA38: 11 | AB38: 11 | AC38: 11 | AD38: 0 | AE38: 0 | AF38: 0 | AG38: 12 | AH38: 15 | AI38: 13 | AJ38: 15

Sheet Converted Per-90 Preview
A1: Player | B1: Position | C1: xg90 | D1: npxg90 | E1: xa90 | F1: shots90 | G1: shots_on_target90 | H1: goals90 | I1: key_passes90 | J1: tackles90 | K1: interceptions90 | L1: clearances90 | M1: blocks90 | N1: ball_recoveries90 | O1: dribbles90 | P1: dribble_pct | Q1: duels_won_pct | R1: pass_pct | S1: long_balls90 | T1: long_ball_pct | U1: aerials_won90 | V1: aerials_won_pct | W1: assists90 | X1: big_chances_created90 | Y1: big_chances_missed90 | Z1: possession_lost90 | AA1: penalty_goals90 | AB1: xg_chain90 | AC1: xg_buildup90 | AD1: saves90 | AE1: goals_prevented90 | AF1: clean_sheet_pct | AG1: goals_conceded90 | AH1: yellow_cards90 | AI1: red_cards90 | AJ1: rating
A2: ='Legend Attributes'!A2 -> Eden Hazard | B2: ='Legend Attributes'!B2 -> W | C2: =IF('Legend Attributes'!C2=0,0,ROUND(IF(INDEX('Conversion Range'!$E$2:$E$35,MATCH(C$1,'Conversion Range'!$A$2:$A$35,0))=1,INDEX('Conversion Range'!$D$2:$D$35,MATCH(C$1,'Conversion Range'!$A$2:$A$35,0))-(('Legend Attributes'!C2-1)/19)*(INDEX('Conversion Range'!$D$2:$D$35,MATCH(C$1,'Conversion Range'!$A$2:$A$35,0))-INDEX('Conversion Range'!$C$2:$C$35,MATCH(C$1,'Conversion Range'!$A$2:$A$35,0))),INDEX('Conversion Range'!$C$2:$C$35,MATCH(C$1,'Conversion Range'!$A$2:$A$35,0))+(('Legend Attributes'!C2-1)/19)*(INDEX('Conversion Range'!$D$2:$D$35,MATCH(C$1,'Conversion Range'!$A$2:$A$35,0))-INDEX('Conversion Range'!$C$2:$C$35,MATCH(C$1,'Conversion Range'!$A$2:$A$35,0)))),3)) -> 0.588 | D2: =IF('Legend Attributes'!D2=0,0,ROUND(IF(INDEX('Conversion Range'!$E$2:$E$35,MATCH(D$1,'Conversion Range'!$A$2:$A$35,0))=1,INDEX('Conversion Range'!$D$2:$D$35,MATCH(D$1,'Conversion Range'!$A$2:$A$35,0))-(('Legend Attributes'!D2-1)/19)*(INDEX('Conversion Range'!$D$2:$D$35,MATCH(D$1,'Conversion Range'!$A$2:$A$35,0))-INDEX('Conversion Range'!$C$2:$C$35,MATCH(D$1,'Conversion Range'!$A$2:$A$35,0))),INDEX('Conversion Range'!$C$2:$C$35,MATCH(D$1,'Conversion Range'!$A$2:$A$35,0))+(('Legend Attributes'!D2-1)/19)*(INDEX('Conversion Range'!$D$2:$D$35,MATCH(D$1,'Conversion Range'!$A$2:$A$35,0))-INDEX('Conversion Range'!$C$2:$C$35,MATCH(D$1,'Conversion Range'!$A$2:$A$35,0)))),3)) -> 0.519 | E2: =IF('Legend Attributes'!E2=0,0,ROUND(IF(INDEX('Conversion Range'!$E$2:$E$35,MATCH(E$1,'Conversion Range'!$A$2:$A$35,0))=1,INDEX('Conversion Range'!$D$2:$D$35,MATCH(E$1,'Conversion Range'!$A$2:$A$35,0))-(('Legend Attributes'!E2-1)/19)*(INDEX('Conversion Range'!$D$2:$D$35,MATCH(E$1,'Conversion Range'!$A$2:$A$35,0))-INDEX('Conversion Range'!$C$2:$C$35,MATCH(E$1,'Conversion Range'!$A$2:$A$35,0))),INDEX('Conversion Range'!$C$2:$C$35,MATCH(E$1,'Conversion Range'!$A$2:$A$35,0))+(('Legend Attributes'!E2-1)/19)*(INDEX('Conversion Range'!$D$2:$D$35,MATCH(E$1,'Conversion Range'!$A$2:$A$35,0))-INDEX('Conversion Range'!$C$2:$C$35,MATCH(E$1,'Conversion Range'!$A$2:$A$35,0)))),3)) -> 0.465 | F2: =IF('Legend Attributes'!F2=0,0,ROUND(IF(INDEX('Conversion Range'!$E$2:$E$35,MATCH(F$1,'Conversion Range'!$A$2:$A$35,0))=1,INDEX('Conversion Range'!$D$2:$D$35,MATCH(F$1,'Conversion Range'!$A$2:$A$35,0))-(('Legend Attributes'!F2-1)/19)*(INDEX('Conversion Range'!$D$2:$D$35,MATCH(F$1,'Conversion Range'!$A$2:$A$35,0))-INDEX('Conversion Range'!$C$2:$C$35,MATCH(F$1,'Conversion Range'!$A$2:$A$35,0))),INDEX('Conversion Range'!$C$2:$C$35,MATCH(F$1,'Conversion Range'!$A$2:$A$35,0))+(('Legend Attributes'!F2-1)/19)*(INDEX('Conversion Range'!$D$2:$D$35,MATCH(F$1,'Conversion Range'!$A$2:$A$35,0))-INDEX('Conversion Range'!$C$2:$C$35,MATCH(F$1,'Conversion Range'!$A$2:$A$35,0)))),3)) -> 2.379 | G2: =IF('Legend Attributes'!G2=0,0,ROUND(IF(INDEX('Conversion Range'!$E$2:$E$35,MATCH(G$1,'Conversion Range'!$A$2:$A$35,0))=1,INDEX('Conversion Range'!$D$2:$D$35,MATCH(G$1,'Conversion Range'!$A$2:$A$35,0))-(('Legend Attributes'!G2-1)/19)*(INDEX('Conversion Range'!$D$2:$D$35,MATCH(G$1,'Conversion Range'!$A$2:$A$35,0))-INDEX('Conversion Range'!$C$2:$C$35,MATCH(G$1,'Conversion Range'!$A$2:$A$35,0))),INDEX('Conversion Range'!$C$2:$C$35,MATCH(G$1,'Conversion Range'!$A$2:$A$35,0))+(('Legend Attributes'!G2-1)/19)*(INDEX('Conversion Range'!$D$2:$D$35,MATCH(G$1,'Conversion Range'!$A$2:$A$35,0))-INDEX('Conversion Range'!$C$2:$C$35,MATCH(G$1,'Conversion Range'!$A$2:$A$35,0)))),3)) -> 1.365 | H2: =IF('Legend Attributes'!H2=0,0,ROUND(IF(INDEX('Conversion Range'!$E$2:$E$35,MATCH(H$1,'Conversion Range'!$A$2:$A$35,0))=1,INDEX('Conversion Range'!$D$2:$D$35,MATCH(H$1,'Conversion Range'!$A$2:$A$35,0))-(('Legend Attributes'!H2-1)/19)*(INDEX('Conversion Range'!$D$2:$D$35,MATCH(H$1,'Conversion Range'!$A$2:$A$35,0))-INDEX('Conversion Range'!$C$2:$C$35,MATCH(H$1,'Conversion Range'!$A$2:$A$35,0))),INDEX('Conversion Range'!$C$2:$C$35,MATCH(H$1,'Conversion Range'!$A$2:$A$35,0))+(('Legend Attributes'!H2-1)/19)*(INDEX('Conversion Range'!$D$2:$D$35,MATCH(H$1,'Conversion Range'!$A$2:$A$35,0))-INDEX('Conversion Range'!$C$2:$C$35,MATCH(H$1,'Conversion Range'!$A$2:$A$35,0)))),3)) -> 0.684 | I2: =IF('Legend Attributes'!I2=0,0,ROUND(IF(INDEX('Conversion Range'!$E$2:$E$35,MATCH(I$1,'Conversion Range'!$A$2:$A$35,0))=1,INDEX('Conversion Range'!$D$2:$D$35,MATCH(I$1,'Conversion Range'!$A$2:$A$35,0))-(('Legend Attributes'!I2-1)/19)*(INDEX('Conversion Range'!$D$2:$D$35,MATCH(I$1,'Conversion Range'!$A$2:$A$35,0))-INDEX('Conversion Range'!$C$2:$C$35,MATCH(I$1,'Conversion Range'!$A$2:$A$35,0))),INDEX('Conversion Range'!$C$2:$C$35,MATCH(I$1,'Conversion Range'!$A$2:$A$35,0))+(('Legend Attributes'!I2-1)/19)*(INDEX('Conversion Range'!$D$2:$D$35,MATCH(I$1,'Conversion Range'!$A$2:$A$35,0))-INDEX('Conversion Range'!$C$2:$C$35,MATCH(I$1,'Conversion Range'!$A$2:$A$35,0)))),3)) -> 2.074 | J2: =IF('Legend Attributes'!J2=0,0,ROUND(IF(INDEX('Conversion Range'!$E$2:$E$35,MATCH(J$1,'Conversion Range'!$A$2:$A$35,0))=1,INDEX('Conversion Range'!$D$2:$D$35,MATCH(J$1,'Conversion Range'!$A$2:$A$35,0))-(('Legend Attributes'!J2-1)/19)*(INDEX('Conversion Range'!$D$2:$D$35,MATCH(J$1,'Conversion Range'!$A$2:$A$35,0))-INDEX('Conversion Range'!$C$2:$C$35,MATCH(J$1,'Conversion Range'!$A$2:$A$35,0))),INDEX('Conversion Range'!$C$2:$C$35,MATCH(J$1,'Conversion Range'!$A$2:$A$35,0))+(('Legend Attributes'!J2-1)/19)*(INDEX('Conversion Range'!$D$2:$D$35,MATCH(J$1,'Conversion Range'!$A$2:$A$35,0))-INDEX('Conversion Range'!$C$2:$C$35,MATCH(J$1,'Conversion Range'!$A$2:$A$35,0)))),3)) -> 1.016 | ... AJ2: =IF('Legend Attributes'!AJ2=0,0,ROUND(IF(INDEX('Conversion Range'!$E$2:$E$35,MATCH(AJ$1,'Conversion Range'!$A$2:$A$35,0))=1,INDEX('Conversion Range'!$D$2:$D$35,MATCH(AJ$1,'Conversion Range'!$A$2:$A$35,0))-(('Legend Attributes'!AJ2-1)/19)*(INDEX('Conversion Range'!$D$2:$D$35,MATCH(AJ$1,'Conversion Range'!$A$2:$A$35,0))-INDEX('Conversion Range'!$C$2:$C$35,MATCH(AJ$1,'Conversion Range'!$A$2:$A$35,0))),INDEX('Conversion Range'!$C$2:$C$35,MATCH(AJ$1,'Conversion Range'!$A$2:$A$35,0))+(('Legend Attributes'!AJ2-1)/19)*(INDEX('Conversion Range'!$D$2:$D$35,MATCH(AJ$1,'Conversion Range'!$A$2:$A$35,0))-INDEX('Conversion Range'!$C$2:$C$35,MATCH(AJ$1,'Conversion Range'!$A$2:$A$35,0)))),3)) -> 7.916
A3: ='Legend Attributes'!A3 -> Luis Suárez | B3: ='Legend Attributes'!B3 -> ST | C3: =IF('Legend Attributes'!C3=0,0,ROUND(IF(INDEX('Conversion Range'!$E$2:$E$35,MATCH(C$1,'Conversion Range'!$A$2:$A$35,0))=1,INDEX('Conversion Range'!$D$2:$D$35,MATCH(C$1,'Conversion Range'!$A$2:$A$35,0))-(('Legend Attributes'!C3-1)/19)*(INDEX('Conversion Range'!$D$2:$D$35,MATCH(C$1,'Conversion Range'!$A$2:$A$35,0))-INDEX('Conversion Range'!$C$2:$C$35,MATCH(C$1,'Conversion Range'!$A$2:$A$35,0))),INDEX('Conversion Range'!$C$2:$C$35,MATCH(C$1,'Conversion Range'!$A$2:$A$35,0))+(('Legend Attributes'!C3-1)/19)*(INDEX('Conversion Range'!$D$2:$D$35,MATCH(C$1,'Conversion Range'!$A$2:$A$35,0))-INDEX('Conversion Range'!$C$2:$C$35,MATCH(C$1,'Conversion Range'!$A$2:$A$35,0)))),3)) -> 0.719 | D3: =IF('Legend Attributes'!D3=0,0,ROUND(IF(INDEX('Conversion Range'!$E$2:$E$35,MATCH(D$1,'Conversion Range'!$A$2:$A$35,0))=1,INDEX('Conversion Range'!$D$2:$D$35,MATCH(D$1,'Conversion Range'!$A$2:$A$35,0))-(('Legend Attributes'!D3-1)/19)*(INDEX('Conversion Range'!$D$2:$D$35,MATCH(D$1,'Conversion Range'!$A$2:$A$35,0))-INDEX('Conversion Range'!$C$2:$C$35,MATCH(D$1,'Conversion Range'!$A$2:$A$35,0))),INDEX('Conversion Range'!$C$2:$C$35,MATCH(D$1,'Conversion Range'!$A$2:$A$35,0))+(('Legend Attributes'!D3-1)/19)*(INDEX('Conversion Range'!$D$2:$D$35,MATCH(D$1,'Conversion Range'!$A$2:$A$35,0))-INDEX('Conversion Range'!$C$2:$C$35,MATCH(D$1,'Conversion Range'!$A$2:$A$35,0)))),3)) -> 0.596 | E3: =IF('Legend Attributes'!E3=0,0,ROUND(IF(INDEX('Conversion Range'!$E$2:$E$35,MATCH(E$1,'Conversion Range'!$A$2:$A$35,0))=1,INDEX('Conversion Range'!$D$2:$D$35,MATCH(E$1,'Conversion Range'!$A$2:$A$35,0))-(('Legend Attributes'!E3-1)/19)*(INDEX('Conversion Range'!$D$2:$D$35,MATCH(E$1,'Conversion Range'!$A$2:$A$35,0))-INDEX('Conversion Range'!$C$2:$C$35,MATCH(E$1,'Conversion Range'!$A$2:$A$35,0))),INDEX('Conversion Range'!$C$2:$C$35,MATCH(E$1,'Conversion Range'!$A$2:$A$35,0))+(('Legend Attributes'!E3-1)/19)*(INDEX('Conversion Range'!$D$2:$D$35,MATCH(E$1,'Conversion Range'!$A$2:$A$35,0))-INDEX('Conversion Range'!$C$2:$C$35,MATCH(E$1,'Conversion Range'!$A$2:$A$35,0)))),3)) -> 0.379 | F3: =IF('Legend Attributes'!F3=0,0,ROUND(IF(INDEX('Conversion Range'!$E$2:$E$35,MATCH(F$1,'Conversion Range'!$A$2:$A$35,0))=1,INDEX('Conversion Range'!$D$2:$D$35,MATCH(F$1,'Conversion Range'!$A$2:$A$35,0))-(('Legend Attributes'!F3-1)/19)*(INDEX('Conversion Range'!$D$2:$D$35,MATCH(F$1,'Conversion Range'!$A$2:$A$35,0))-INDEX('Conversion Range'!$C$2:$C$35,MATCH(F$1,'Conversion Range'!$A$2:$A$35,0))),INDEX('Conversion Range'!$C$2:$C$35,MATCH(F$1,'Conversion Range'!$A$2:$A$35,0))+(('Legend Attributes'!F3-1)/19)*(INDEX('Conversion Range'!$D$2:$D$35,MATCH(F$1,'Conversion Range'!$A$2:$A$35,0))-INDEX('Conversion Range'!$C$2:$C$35,MATCH(F$1,'Conversion Range'!$A$2:$A$35,0)))),3)) -> 3.189 | G3: =IF('Legend Attributes'!G3=0,0,ROUND(IF(INDEX('Conversion Range'!$E$2:$E$35,MATCH(G$1,'Conversion Range'!$A$2:$A$35,0))=1,INDEX('Conversion Range'!$D$2:$D$35,MATCH(G$1,'Conversion Range'!$A$2:$A$35,0))-(('Legend Attributes'!G3-1)/19)*(INDEX('Conversion Range'!$D$2:$D$35,MATCH(G$1,'Conversion Range'!$A$2:$A$35,0))-INDEX('Conversion Range'!$C$2:$C$35,MATCH(G$1,'Conversion Range'!$A$2:$A$35,0))),INDEX('Conversion Range'!$C$2:$C$35,MATCH(G$1,'Conversion Range'!$A$2:$A$35,0))+(('Legend Attributes'!G3-1)/19)*(INDEX('Conversion Range'!$D$2:$D$35,MATCH(G$1,'Conversion Range'!$A$2:$A$35,0))-INDEX('Conversion Range'!$C$2:$C$35,MATCH(G$1,'Conversion Range'!$A$2:$A$35,0)))),3)) -> 1.716 | H3: =IF('Legend Attributes'!H3=0,0,ROUND(IF(INDEX('Conversion Range'!$E$2:$E$35,MATCH(H$1,'Conversion Range'!$A$2:$A$35,0))=1,INDEX('Conversion Range'!$D$2:$D$35,MATCH(H$1,'Conversion Range'!$A$2:$A$35,0))-(('Legend Attributes'!H3-1)/19)*(INDEX('Conversion Range'!$D$2:$D$35,MATCH(H$1,'Conversion Range'!$A$2:$A$35,0))-INDEX('Conversion Range'!$C$2:$C$35,MATCH(H$1,'Conversion Range'!$A$2:$A$35,0))),INDEX('Conversion Range'!$C$2:$C$35,MATCH(H$1,'Conversion Range'!$A$2:$A$35,0))+(('Legend Attributes'!H3-1)/19)*(INDEX('Conversion Range'!$D$2:$D$35,MATCH(H$1,'Conversion Range'!$A$2:$A$35,0))-INDEX('Conversion Range'!$C$2:$C$35,MATCH(H$1,'Conversion Range'!$A$2:$A$35,0)))),3)) -> 0.842 | I3: =IF('Legend Attributes'!I3=0,0,ROUND(IF(INDEX('Conversion Range'!$E$2:$E$35,MATCH(I$1,'Conversion Range'!$A$2:$A$35,0))=1,INDEX('Conversion Range'!$D$2:$D$35,MATCH(I$1,'Conversion Range'!$A$2:$A$35,0))-(('Legend Attributes'!I3-1)/19)*(INDEX('Conversion Range'!$D$2:$D$35,MATCH(I$1,'Conversion Range'!$A$2:$A$35,0))-INDEX('Conversion Range'!$C$2:$C$35,MATCH(I$1,'Conversion Range'!$A$2:$A$35,0))),INDEX('Conversion Range'!$C$2:$C$35,MATCH(I$1,'Conversion Range'!$A$2:$A$35,0))+(('Legend Attributes'!I3-1)/19)*(INDEX('Conversion Range'!$D$2:$D$35,MATCH(I$1,'Conversion Range'!$A$2:$A$35,0))-INDEX('Conversion Range'!$C$2:$C$35,MATCH(I$1,'Conversion Range'!$A$2:$A$35,0)))),3)) -> 1.547 | J3: =IF('Legend Attributes'!J3=0,0,ROUND(IF(INDEX('Conversion Range'!$E$2:$E$35,MATCH(J$1,'Conversion Range'!$A$2:$A$35,0))=1,INDEX('Conversion Range'!$D$2:$D$35,MATCH(J$1,'Conversion Range'!$A$2:$A$35,0))-(('Legend Attributes'!J3-1)/19)*(INDEX('Conversion Range'!$D$2:$D$35,MATCH(J$1,'Conversion Range'!$A$2:$A$35,0))-INDEX('Conversion Range'!$C$2:$C$35,MATCH(J$1,'Conversion Range'!$A$2:$A$35,0))),INDEX('Conversion Range'!$C$2:$C$35,MATCH(J$1,'Conversion Range'!$A$2:$A$35,0))+(('Legend Attributes'!J3-1)/19)*(INDEX('Conversion Range'!$D$2:$D$35,MATCH(J$1,'Conversion Range'!$A$2:$A$35,0))-INDEX('Conversion Range'!$C$2:$C$35,MATCH(J$1,'Conversion Range'!$A$2:$A$35,0)))),3)) -> 1.179 | ... AJ3: =IF('Legend Attributes'!AJ3=0,0,ROUND(IF(INDEX('Conversion Range'!$E$2:$E$35,MATCH(AJ$1,'Conversion Range'!$A$2:$A$35,0))=1,INDEX('Conversion Range'!$D$2:$D$35,MATCH(AJ$1,'Conversion Range'!$A$2:$A$35,0))-(('Legend Attributes'!AJ3-1)/19)*(INDEX('Conversion Range'!$D$2:$D$35,MATCH(AJ$1,'Conversion Range'!$A$2:$A$35,0))-INDEX('Conversion Range'!$C$2:$C$35,MATCH(AJ$1,'Conversion Range'!$A$2:$A$35,0))),INDEX('Conversion Range'!$C$2:$C$35,MATCH(AJ$1,'Conversion Range'!$A$2:$A$35,0))+(('Legend Attributes'!AJ3-1)/19)*(INDEX('Conversion Range'!$D$2:$D$35,MATCH(AJ$1,'Conversion Range'!$A$2:$A$35,0))-INDEX('Conversion Range'!$C$2:$C$35,MATCH(AJ$1,'Conversion Range'!$A$2:$A$35,0)))),3)) -> 7.916
A4: ='Legend Attributes'!A4 -> Sergio Agüero | B4: ='Legend Attributes'!B4 -> ST | C4: =IF('Legend Attributes'!C4=0,0,ROUND(IF(INDEX('Conversion Range'!$E$2:$E$35,MATCH(C$1,'Conversion Range'!$A$2:$A$35,0))=1,INDEX('Conversion Range'!$D$2:$D$35,MATCH(C$1,'Conversion Range'!$A$2:$A$35,0))-(('Legend Attributes'!C4-1)/19)*(INDEX('Conversion Range'!$D$2:$D$35,MATCH(C$1,'Conversion Range'!$A$2:$A$35,0))-INDEX('Conversion Range'!$C$2:$C$35,MATCH(C$1,'Conversion Range'!$A$2:$A$35,0))),INDEX('Conversion Range'!$C$2:$C$35,MATCH(C$1,'Conversion Range'!$A$2:$A$35,0))+(('Legend Attributes'!C4-1)/19)*(INDEX('Conversion Range'!$D$2:$D$35,MATCH(C$1,'Conversion Range'!$A$2:$A$35,0))-INDEX('Conversion Range'!$C$2:$C$35,MATCH(C$1,'Conversion Range'!$A$2:$A$35,0)))),3)) -> 0.675 | D4: =IF('Legend Attributes'!D4=0,0,ROUND(IF(INDEX('Conversion Range'!$E$2:$E$35,MATCH(D$1,'Conversion Range'!$A$2:$A$35,0))=1,INDEX('Conversion Range'!$D$2:$D$35,MATCH(D$1,'Conversion Range'!$A$2:$A$35,0))-(('Legend Attributes'!D4-1)/19)*(INDEX('Conversion Range'!$D$2:$D$35,MATCH(D$1,'Conversion Range'!$A$2:$A$35,0))-INDEX('Conversion Range'!$C$2:$C$35,MATCH(D$1,'Conversion Range'!$A$2:$A$35,0))),INDEX('Conversion Range'!$C$2:$C$35,MATCH(D$1,'Conversion Range'!$A$2:$A$35,0))+(('Legend Attributes'!D4-1)/19)*(INDEX('Conversion Range'!$D$2:$D$35,MATCH(D$1,'Conversion Range'!$A$2:$A$35,0))-INDEX('Conversion Range'!$C$2:$C$35,MATCH(D$1,'Conversion Range'!$A$2:$A$35,0)))),3)) -> 0.596 | E4: =IF('Legend Attributes'!E4=0,0,ROUND(IF(INDEX('Conversion Range'!$E$2:$E$35,MATCH(E$1,'Conversion Range'!$A$2:$A$35,0))=1,INDEX('Conversion Range'!$D$2:$D$35,MATCH(E$1,'Conversion Range'!$A$2:$A$35,0))-(('Legend Attributes'!E4-1)/19)*(INDEX('Conversion Range'!$D$2:$D$35,MATCH(E$1,'Conversion Range'!$A$2:$A$35,0))-INDEX('Conversion Range'!$C$2:$C$35,MATCH(E$1,'Conversion Range'!$A$2:$A$35,0))),INDEX('Conversion Range'!$C$2:$C$35,MATCH(E$1,'Conversion Range'!$A$2:$A$35,0))+(('Legend Attributes'!E4-1)/19)*(INDEX('Conversion Range'!$D$2:$D$35,MATCH(E$1,'Conversion Range'!$A$2:$A$35,0))-INDEX('Conversion Range'!$C$2:$C$35,MATCH(E$1,'Conversion Range'!$A$2:$A$35,0)))),3)) -> 0.237 | F4: =IF('Legend Attributes'!F4=0,0,ROUND(IF(INDEX('Conversion Range'!$E$2:$E$35,MATCH(F$1,'Conversion Range'!$A$2:$A$35,0))=1,INDEX('Conversion Range'!$D$2:$D$35,MATCH(F$1,'Conversion Range'!$A$2:$A$35,0))-(('Legend Attributes'!F4-1)/19)*(INDEX('Conversion Range'!$D$2:$D$35,MATCH(F$1,'Conversion Range'!$A$2:$A$35,0))-INDEX('Conversion Range'!$C$2:$C$35,MATCH(F$1,'Conversion Range'!$A$2:$A$35,0))),INDEX('Conversion Range'!$C$2:$C$35,MATCH(F$1,'Conversion Range'!$A$2:$A$35,0))+(('Legend Attributes'!F4-1)/19)*(INDEX('Conversion Range'!$D$2:$D$35,MATCH(F$1,'Conversion Range'!$A$2:$A$35,0))-INDEX('Conversion Range'!$C$2:$C$35,MATCH(F$1,'Conversion Range'!$A$2:$A$35,0)))),3)) -> 2.987 | G4: =IF('Legend Attributes'!G4=0,0,ROUND(IF(INDEX('Conversion Range'!$E$2:$E$35,MATCH(G$1,'Conversion Range'!$A$2:$A$35,0))=1,INDEX('Conversion Range'!$D$2:$D$35,MATCH(G$1,'Conversion Range'!$A$2:$A$35,0))-(('Legend Attributes'!G4-1)/19)*(INDEX('Conversion Range'!$D$2:$D$35,MATCH(G$1,'Conversion Range'!$A$2:$A$35,0))-INDEX('Conversion Range'!$C$2:$C$35,MATCH(G$1,'Conversion Range'!$A$2:$A$35,0))),INDEX('Conversion Range'!$C$2:$C$35,MATCH(G$1,'Conversion Range'!$A$2:$A$35,0))+(('Legend Attributes'!G4-1)/19)*(INDEX('Conversion Range'!$D$2:$D$35,MATCH(G$1,'Conversion Range'!$A$2:$A$35,0))-INDEX('Conversion Range'!$C$2:$C$35,MATCH(G$1,'Conversion Range'!$A$2:$A$35,0)))),3)) -> 1.716 | H4: =IF('Legend Attributes'!H4=0,0,ROUND(IF(INDEX('Conversion Range'!$E$2:$E$35,MATCH(H$1,'Conversion Range'!$A$2:$A$35,0))=1,INDEX('Conversion Range'!$D$2:$D$35,MATCH(H$1,'Conversion Range'!$A$2:$A$35,0))-(('Legend Attributes'!H4-1)/19)*(INDEX('Conversion Range'!$D$2:$D$35,MATCH(H$1,'Conversion Range'!$A$2:$A$35,0))-INDEX('Conversion Range'!$C$2:$C$35,MATCH(H$1,'Conversion Range'!$A$2:$A$35,0))),INDEX('Conversion Range'!$C$2:$C$35,MATCH(H$1,'Conversion Range'!$A$2:$A$35,0))+(('Legend Attributes'!H4-1)/19)*(INDEX('Conversion Range'!$D$2:$D$35,MATCH(H$1,'Conversion Range'!$A$2:$A$35,0))-INDEX('Conversion Range'!$C$2:$C$35,MATCH(H$1,'Conversion Range'!$A$2:$A$35,0)))),3)) -> 0.895 | I4: =IF('Legend Attributes'!I4=0,0,ROUND(IF(INDEX('Conversion Range'!$E$2:$E$35,MATCH(I$1,'Conversion Range'!$A$2:$A$35,0))=1,INDEX('Conversion Range'!$D$2:$D$35,MATCH(I$1,'Conversion Range'!$A$2:$A$35,0))-(('Legend Attributes'!I4-1)/19)*(INDEX('Conversion Range'!$D$2:$D$35,MATCH(I$1,'Conversion Range'!$A$2:$A$35,0))-INDEX('Conversion Range'!$C$2:$C$35,MATCH(I$1,'Conversion Range'!$A$2:$A$35,0))),INDEX('Conversion Range'!$C$2:$C$35,MATCH(I$1,'Conversion Range'!$A$2:$A$35,0))+(('Legend Attributes'!I4-1)/19)*(INDEX('Conversion Range'!$D$2:$D$35,MATCH(I$1,'Conversion Range'!$A$2:$A$35,0))-INDEX('Conversion Range'!$C$2:$C$35,MATCH(I$1,'Conversion Range'!$A$2:$A$35,0)))),3)) -> 0.889 | J4: =IF('Legend Attributes'!J4=0,0,ROUND(IF(INDEX('Conversion Range'!$E$2:$E$35,MATCH(J$1,'Conversion Range'!$A$2:$A$35,0))=1,INDEX('Conversion Range'!$D$2:$D$35,MATCH(J$1,'Conversion Range'!$A$2:$A$35,0))-(('Legend Attributes'!J4-1)/19)*(INDEX('Conversion Range'!$D$2:$D$35,MATCH(J$1,'Conversion Range'!$A$2:$A$35,0))-INDEX('Conversion Range'!$C$2:$C$35,MATCH(J$1,'Conversion Range'!$A$2:$A$35,0))),INDEX('Conversion Range'!$C$2:$C$35,MATCH(J$1,'Conversion Range'!$A$2:$A$35,0))+(('Legend Attributes'!J4-1)/19)*(INDEX('Conversion Range'!$D$2:$D$35,MATCH(J$1,'Conversion Range'!$A$2:$A$35,0))-INDEX('Conversion Range'!$C$2:$C$35,MATCH(J$1,'Conversion Range'!$A$2:$A$35,0)))),3)) -> 0.526 | ... AJ4: =IF('Legend Attributes'!AJ4=0,0,ROUND(IF(INDEX('Conversion Range'!$E$2:$E$35,MATCH(AJ$1,'Conversion Range'!$A$2:$A$35,0))=1,INDEX('Conversion Range'!$D$2:$D$35,MATCH(AJ$1,'Conversion Range'!$A$2:$A$35,0))-(('Legend Attributes'!AJ4-1)/19)*(INDEX('Conversion Range'!$D$2:$D$35,MATCH(AJ$1,'Conversion Range'!$A$2:$A$35,0))-INDEX('Conversion Range'!$C$2:$C$35,MATCH(AJ$1,'Conversion Range'!$A$2:$A$35,0))),INDEX('Conversion Range'!$C$2:$C$35,MATCH(AJ$1,'Conversion Range'!$A$2:$A$35,0))+(('Legend Attributes'!AJ4-1)/19)*(INDEX('Conversion Range'!$D$2:$D$35,MATCH(AJ$1,'Conversion Range'!$A$2:$A$35,0))-INDEX('Conversion Range'!$C$2:$C$35,MATCH(AJ$1,'Conversion Range'!$A$2:$A$35,0)))),3)) -> 7.916
A5: ='Legend Attributes'!A5 -> Andrés Iniesta | B5: ='Legend Attributes'!B5 -> CM | C5: =IF('Legend Attributes'!C5=0,0,ROUND(IF(INDEX('Conversion Range'!$E$2:$E$35,MATCH(C$1,'Conversion Range'!$A$2:$A$35,0))=1,INDEX('Conversion Range'!$D$2:$D$35,MATCH(C$1,'Conversion Range'!$A$2:$A$35,0))-(('Legend Attributes'!C5-1)/19)*(INDEX('Conversion Range'!$D$2:$D$35,MATCH(C$1,'Conversion Range'!$A$2:$A$35,0))-INDEX('Conversion Range'!$C$2:$C$35,MATCH(C$1,'Conversion Range'!$A$2:$A$35,0))),INDEX('Conversion Range'!$C$2:$C$35,MATCH(C$1,'Conversion Range'!$A$2:$A$35,0))+(('Legend Attributes'!C5-1)/19)*(INDEX('Conversion Range'!$D$2:$D$35,MATCH(C$1,'Conversion Range'!$A$2:$A$35,0))-INDEX('Conversion Range'!$C$2:$C$35,MATCH(C$1,'Conversion Range'!$A$2:$A$35,0)))),3)) -> 0.282 | D5: =IF('Legend Attributes'!D5=0,0,ROUND(IF(INDEX('Conversion Range'!$E$2:$E$35,MATCH(D$1,'Conversion Range'!$A$2:$A$35,0))=1,INDEX('Conversion Range'!$D$2:$D$35,MATCH(D$1,'Conversion Range'!$A$2:$A$35,0))-(('Legend Attributes'!D5-1)/19)*(INDEX('Conversion Range'!$D$2:$D$35,MATCH(D$1,'Conversion Range'!$A$2:$A$35,0))-INDEX('Conversion Range'!$C$2:$C$35,MATCH(D$1,'Conversion Range'!$A$2:$A$35,0))),INDEX('Conversion Range'!$C$2:$C$35,MATCH(D$1,'Conversion Range'!$A$2:$A$35,0))+(('Legend Attributes'!D5-1)/19)*(INDEX('Conversion Range'!$D$2:$D$35,MATCH(D$1,'Conversion Range'!$A$2:$A$35,0))-INDEX('Conversion Range'!$C$2:$C$35,MATCH(D$1,'Conversion Range'!$A$2:$A$35,0)))),3)) -> 0.251 | E5: =IF('Legend Attributes'!E5=0,0,ROUND(IF(INDEX('Conversion Range'!$E$2:$E$35,MATCH(E$1,'Conversion Range'!$A$2:$A$35,0))=1,INDEX('Conversion Range'!$D$2:$D$35,MATCH(E$1,'Conversion Range'!$A$2:$A$35,0))-(('Legend Attributes'!E5-1)/19)*(INDEX('Conversion Range'!$D$2:$D$35,MATCH(E$1,'Conversion Range'!$A$2:$A$35,0))-INDEX('Conversion Range'!$C$2:$C$35,MATCH(E$1,'Conversion Range'!$A$2:$A$35,0))),INDEX('Conversion Range'!$C$2:$C$35,MATCH(E$1,'Conversion Range'!$A$2:$A$35,0))+(('Legend Attributes'!E5-1)/19)*(INDEX('Conversion Range'!$D$2:$D$35,MATCH(E$1,'Conversion Range'!$A$2:$A$35,0))-INDEX('Conversion Range'!$C$2:$C$35,MATCH(E$1,'Conversion Range'!$A$2:$A$35,0)))),3)) -> 0.436 | F5: =IF('Legend Attributes'!F5=0,0,ROUND(IF(INDEX('Conversion Range'!$E$2:$E$35,MATCH(F$1,'Conversion Range'!$A$2:$A$35,0))=1,INDEX('Conversion Range'!$D$2:$D$35,MATCH(F$1,'Conversion Range'!$A$2:$A$35,0))-(('Legend Attributes'!F5-1)/19)*(INDEX('Conversion Range'!$D$2:$D$35,MATCH(F$1,'Conversion Range'!$A$2:$A$35,0))-INDEX('Conversion Range'!$C$2:$C$35,MATCH(F$1,'Conversion Range'!$A$2:$A$35,0))),INDEX('Conversion Range'!$C$2:$C$35,MATCH(F$1,'Conversion Range'!$A$2:$A$35,0))+(('Legend Attributes'!F5-1)/19)*(INDEX('Conversion Range'!$D$2:$D$35,MATCH(F$1,'Conversion Range'!$A$2:$A$35,0))-INDEX('Conversion Range'!$C$2:$C$35,MATCH(F$1,'Conversion Range'!$A$2:$A$35,0)))),3)) -> 0.961 | G5: =IF('Legend Attributes'!G5=0,0,ROUND(IF(INDEX('Conversion Range'!$E$2:$E$35,MATCH(G$1,'Conversion Range'!$A$2:$A$35,0))=1,INDEX('Conversion Range'!$D$2:$D$35,MATCH(G$1,'Conversion Range'!$A$2:$A$35,0))-(('Legend Attributes'!G5-1)/19)*(INDEX('Conversion Range'!$D$2:$D$35,MATCH(G$1,'Conversion Range'!$A$2:$A$35,0))-INDEX('Conversion Range'!$C$2:$C$35,MATCH(G$1,'Conversion Range'!$A$2:$A$35,0))),INDEX('Conversion Range'!$C$2:$C$35,MATCH(G$1,'Conversion Range'!$A$2:$A$35,0))+(('Legend Attributes'!G5-1)/19)*(INDEX('Conversion Range'!$D$2:$D$35,MATCH(G$1,'Conversion Range'!$A$2:$A$35,0))-INDEX('Conversion Range'!$C$2:$C$35,MATCH(G$1,'Conversion Range'!$A$2:$A$35,0)))),3)) -> 0.547 | H5: =IF('Legend Attributes'!H5=0,0,ROUND(IF(INDEX('Conversion Range'!$E$2:$E$35,MATCH(H$1,'Conversion Range'!$A$2:$A$35,0))=1,INDEX('Conversion Range'!$D$2:$D$35,MATCH(H$1,'Conversion Range'!$A$2:$A$35,0))-(('Legend Attributes'!H5-1)/19)*(INDEX('Conversion Range'!$D$2:$D$35,MATCH(H$1,'Conversion Range'!$A$2:$A$35,0))-INDEX('Conversion Range'!$C$2:$C$35,MATCH(H$1,'Conversion Range'!$A$2:$A$35,0))),INDEX('Conversion Range'!$C$2:$C$35,MATCH(H$1,'Conversion Range'!$A$2:$A$35,0))+(('Legend Attributes'!H5-1)/19)*(INDEX('Conversion Range'!$D$2:$D$35,MATCH(H$1,'Conversion Range'!$A$2:$A$35,0))-INDEX('Conversion Range'!$C$2:$C$35,MATCH(H$1,'Conversion Range'!$A$2:$A$35,0)))),3)) -> 0.263 | I5: =IF('Legend Attributes'!I5=0,0,ROUND(IF(INDEX('Conversion Range'!$E$2:$E$35,MATCH(I$1,'Conversion Range'!$A$2:$A$35,0))=1,INDEX('Conversion Range'!$D$2:$D$35,MATCH(I$1,'Conversion Range'!$A$2:$A$35,0))-(('Legend Attributes'!I5-1)/19)*(INDEX('Conversion Range'!$D$2:$D$35,MATCH(I$1,'Conversion Range'!$A$2:$A$35,0))-INDEX('Conversion Range'!$C$2:$C$35,MATCH(I$1,'Conversion Range'!$A$2:$A$35,0))),INDEX('Conversion Range'!$C$2:$C$35,MATCH(I$1,'Conversion Range'!$A$2:$A$35,0))+(('Legend Attributes'!I5-1)/19)*(INDEX('Conversion Range'!$D$2:$D$35,MATCH(I$1,'Conversion Range'!$A$2:$A$35,0))-INDEX('Conversion Range'!$C$2:$C$35,MATCH(I$1,'Conversion Range'!$A$2:$A$35,0)))),3)) -> 2.205 | J5: =IF('Legend Attributes'!J5=0,0,ROUND(IF(INDEX('Conversion Range'!$E$2:$E$35,MATCH(J$1,'Conversion Range'!$A$2:$A$35,0))=1,INDEX('Conversion Range'!$D$2:$D$35,MATCH(J$1,'Conversion Range'!$A$2:$A$35,0))-(('Legend Attributes'!J5-1)/19)*(INDEX('Conversion Range'!$D$2:$D$35,MATCH(J$1,'Conversion Range'!$A$2:$A$35,0))-INDEX('Conversion Range'!$C$2:$C$35,MATCH(J$1,'Conversion Range'!$A$2:$A$35,0))),INDEX('Conversion Range'!$C$2:$C$35,MATCH(J$1,'Conversion Range'!$A$2:$A$35,0))+(('Legend Attributes'!J5-1)/19)*(INDEX('Conversion Range'!$D$2:$D$35,MATCH(J$1,'Conversion Range'!$A$2:$A$35,0))-INDEX('Conversion Range'!$C$2:$C$35,MATCH(J$1,'Conversion Range'!$A$2:$A$35,0)))),3)) -> 1.342 | ... AJ5: =IF('Legend Attributes'!AJ5=0,0,ROUND(IF(INDEX('Conversion Range'!$E$2:$E$35,MATCH(AJ$1,'Conversion Range'!$A$2:$A$35,0))=1,INDEX('Conversion Range'!$D$2:$D$35,MATCH(AJ$1,'Conversion Range'!$A$2:$A$35,0))-(('Legend Attributes'!AJ5-1)/19)*(INDEX('Conversion Range'!$D$2:$D$35,MATCH(AJ$1,'Conversion Range'!$A$2:$A$35,0))-INDEX('Conversion Range'!$C$2:$C$35,MATCH(AJ$1,'Conversion Range'!$A$2:$A$35,0))),INDEX('Conversion Range'!$C$2:$C$35,MATCH(AJ$1,'Conversion Range'!$A$2:$A$35,0))+(('Legend Attributes'!AJ5-1)/19)*(INDEX('Conversion Range'!$D$2:$D$35,MATCH(AJ$1,'Conversion Range'!$A$2:$A$35,0))-INDEX('Conversion Range'!$C$2:$C$35,MATCH(AJ$1,'Conversion Range'!$A$2:$A$35,0)))),3)) -> 8.011
A6: ='Legend Attributes'!A6 -> Arjen Robben | B6: ='Legend Attributes'!B6 -> W | C6: =IF('Legend Attributes'!C6=0,0,ROUND(IF(INDEX('Conversion Range'!$E$2:$E$35,MATCH(C$1,'Conversion Range'!$A$2:$A$35,0))=1,INDEX('Conversion Range'!$D$2:$D$35,MATCH(C$1,'Conversion Range'!$A$2:$A$35,0))-(('Legend Attributes'!C6-1)/19)*(INDEX('Conversion Range'!$D$2:$D$35,MATCH(C$1,'Conversion Range'!$A$2:$A$35,0))-INDEX('Conversion Range'!$C$2:$C$35,MATCH(C$1,'Conversion Range'!$A$2:$A$35,0))),INDEX('Conversion Range'!$C$2:$C$35,MATCH(C$1,'Conversion Range'!$A$2:$A$35,0))+(('Legend Attributes'!C6-1)/19)*(INDEX('Conversion Range'!$D$2:$D$35,MATCH(C$1,'Conversion Range'!$A$2:$A$35,0))-INDEX('Conversion Range'!$C$2:$C$35,MATCH(C$1,'Conversion Range'!$A$2:$A$35,0)))),3)) -> 0.675 | D6: =IF('Legend Attributes'!D6=0,0,ROUND(IF(INDEX('Conversion Range'!$E$2:$E$35,MATCH(D$1,'Conversion Range'!$A$2:$A$35,0))=1,INDEX('Conversion Range'!$D$2:$D$35,MATCH(D$1,'Conversion Range'!$A$2:$A$35,0))-(('Legend Attributes'!D6-1)/19)*(INDEX('Conversion Range'!$D$2:$D$35,MATCH(D$1,'Conversion Range'!$A$2:$A$35,0))-INDEX('Conversion Range'!$C$2:$C$35,MATCH(D$1,'Conversion Range'!$A$2:$A$35,0))),INDEX('Conversion Range'!$C$2:$C$35,MATCH(D$1,'Conversion Range'!$A$2:$A$35,0))+(('Legend Attributes'!D6-1)/19)*(INDEX('Conversion Range'!$D$2:$D$35,MATCH(D$1,'Conversion Range'!$A$2:$A$35,0))-INDEX('Conversion Range'!$C$2:$C$35,MATCH(D$1,'Conversion Range'!$A$2:$A$35,0)))),3)) -> 0.596 | E6: =IF('Legend Attributes'!E6=0,0,ROUND(IF(INDEX('Conversion Range'!$E$2:$E$35,MATCH(E$1,'Conversion Range'!$A$2:$A$35,0))=1,INDEX('Conversion Range'!$D$2:$D$35,MATCH(E$1,'Conversion Range'!$A$2:$A$35,0))-(('Legend Attributes'!E6-1)/19)*(INDEX('Conversion Range'!$D$2:$D$35,MATCH(E$1,'Conversion Range'!$A$2:$A$35,0))-INDEX('Conversion Range'!$C$2:$C$35,MATCH(E$1,'Conversion Range'!$A$2:$A$35,0))),INDEX('Conversion Range'!$C$2:$C$35,MATCH(E$1,'Conversion Range'!$A$2:$A$35,0))+(('Legend Attributes'!E6-1)/19)*(INDEX('Conversion Range'!$D$2:$D$35,MATCH(E$1,'Conversion Range'!$A$2:$A$35,0))-INDEX('Conversion Range'!$C$2:$C$35,MATCH(E$1,'Conversion Range'!$A$2:$A$35,0)))),3)) -> 0.294 | F6: =IF('Legend Attributes'!F6=0,0,ROUND(IF(INDEX('Conversion Range'!$E$2:$E$35,MATCH(F$1,'Conversion Range'!$A$2:$A$35,0))=1,INDEX('Conversion Range'!$D$2:$D$35,MATCH(F$1,'Conversion Range'!$A$2:$A$35,0))-(('Legend Attributes'!F6-1)/19)*(INDEX('Conversion Range'!$D$2:$D$35,MATCH(F$1,'Conversion Range'!$A$2:$A$35,0))-INDEX('Conversion Range'!$C$2:$C$35,MATCH(F$1,'Conversion Range'!$A$2:$A$35,0))),INDEX('Conversion Range'!$C$2:$C$35,MATCH(F$1,'Conversion Range'!$A$2:$A$35,0))+(('Legend Attributes'!F6-1)/19)*(INDEX('Conversion Range'!$D$2:$D$35,MATCH(F$1,'Conversion Range'!$A$2:$A$35,0))-INDEX('Conversion Range'!$C$2:$C$35,MATCH(F$1,'Conversion Range'!$A$2:$A$35,0)))),3)) -> 2.987 | G6: =IF('Legend Attributes'!G6=0,0,ROUND(IF(INDEX('Conversion Range'!$E$2:$E$35,MATCH(G$1,'Conversion Range'!$A$2:$A$35,0))=1,INDEX('Conversion Range'!$D$2:$D$35,MATCH(G$1,'Conversion Range'!$A$2:$A$35,0))-(('Legend Attributes'!G6-1)/19)*(INDEX('Conversion Range'!$D$2:$D$35,MATCH(G$1,'Conversion Range'!$A$2:$A$35,0))-INDEX('Conversion Range'!$C$2:$C$35,MATCH(G$1,'Conversion Range'!$A$2:$A$35,0))),INDEX('Conversion Range'!$C$2:$C$35,MATCH(G$1,'Conversion Range'!$A$2:$A$35,0))+(('Legend Attributes'!G6-1)/19)*(INDEX('Conversion Range'!$D$2:$D$35,MATCH(G$1,'Conversion Range'!$A$2:$A$35,0))-INDEX('Conversion Range'!$C$2:$C$35,MATCH(G$1,'Conversion Range'!$A$2:$A$35,0)))),3)) -> 1.599 | H6: =IF('Legend Attributes'!H6=0,0,ROUND(IF(INDEX('Conversion Range'!$E$2:$E$35,MATCH(H$1,'Conversion Range'!$A$2:$A$35,0))=1,INDEX('Conversion Range'!$D$2:$D$35,MATCH(H$1,'Conversion Range'!$A$2:$A$35,0))-(('Legend Attributes'!H6-1)/19)*(INDEX('Conversion Range'!$D$2:$D$35,MATCH(H$1,'Conversion Range'!$A$2:$A$35,0))-INDEX('Conversion Range'!$C$2:$C$35,MATCH(H$1,'Conversion Range'!$A$2:$A$35,0))),INDEX('Conversion Range'!$C$2:$C$35,MATCH(H$1,'Conversion Range'!$A$2:$A$35,0))+(('Legend Attributes'!H6-1)/19)*(INDEX('Conversion Range'!$D$2:$D$35,MATCH(H$1,'Conversion Range'!$A$2:$A$35,0))-INDEX('Conversion Range'!$C$2:$C$35,MATCH(H$1,'Conversion Range'!$A$2:$A$35,0)))),3)) -> 0.789 | I6: =IF('Legend Attributes'!I6=0,0,ROUND(IF(INDEX('Conversion Range'!$E$2:$E$35,MATCH(I$1,'Conversion Range'!$A$2:$A$35,0))=1,INDEX('Conversion Range'!$D$2:$D$35,MATCH(I$1,'Conversion Range'!$A$2:$A$35,0))-(('Legend Attributes'!I6-1)/19)*(INDEX('Conversion Range'!$D$2:$D$35,MATCH(I$1,'Conversion Range'!$A$2:$A$35,0))-INDEX('Conversion Range'!$C$2:$C$35,MATCH(I$1,'Conversion Range'!$A$2:$A$35,0))),INDEX('Conversion Range'!$C$2:$C$35,MATCH(I$1,'Conversion Range'!$A$2:$A$35,0))+(('Legend Attributes'!I6-1)/19)*(INDEX('Conversion Range'!$D$2:$D$35,MATCH(I$1,'Conversion Range'!$A$2:$A$35,0))-INDEX('Conversion Range'!$C$2:$C$35,MATCH(I$1,'Conversion Range'!$A$2:$A$35,0)))),3)) -> 1.284 | J6: =IF('Legend Attributes'!J6=0,0,ROUND(IF(INDEX('Conversion Range'!$E$2:$E$35,MATCH(J$1,'Conversion Range'!$A$2:$A$35,0))=1,INDEX('Conversion Range'!$D$2:$D$35,MATCH(J$1,'Conversion Range'!$A$2:$A$35,0))-(('Legend Attributes'!J6-1)/19)*(INDEX('Conversion Range'!$D$2:$D$35,MATCH(J$1,'Conversion Range'!$A$2:$A$35,0))-INDEX('Conversion Range'!$C$2:$C$35,MATCH(J$1,'Conversion Range'!$A$2:$A$35,0))),INDEX('Conversion Range'!$C$2:$C$35,MATCH(J$1,'Conversion Range'!$A$2:$A$35,0))+(('Legend Attributes'!J6-1)/19)*(INDEX('Conversion Range'!$D$2:$D$35,MATCH(J$1,'Conversion Range'!$A$2:$A$35,0))-INDEX('Conversion Range'!$C$2:$C$35,MATCH(J$1,'Conversion Range'!$A$2:$A$35,0)))),3)) -> 0.853 | ... AJ6: =IF('Legend Attributes'!AJ6=0,0,ROUND(IF(INDEX('Conversion Range'!$E$2:$E$35,MATCH(AJ$1,'Conversion Range'!$A$2:$A$35,0))=1,INDEX('Conversion Range'!$D$2:$D$35,MATCH(AJ$1,'Conversion Range'!$A$2:$A$35,0))-(('Legend Attributes'!AJ6-1)/19)*(INDEX('Conversion Range'!$D$2:$D$35,MATCH(AJ$1,'Conversion Range'!$A$2:$A$35,0))-INDEX('Conversion Range'!$C$2:$C$35,MATCH(AJ$1,'Conversion Range'!$A$2:$A$35,0))),INDEX('Conversion Range'!$C$2:$C$35,MATCH(AJ$1,'Conversion Range'!$A$2:$A$35,0))+(('Legend Attributes'!AJ6-1)/19)*(INDEX('Conversion Range'!$D$2:$D$35,MATCH(AJ$1,'Conversion Range'!$A$2:$A$35,0))-INDEX('Conversion Range'!$C$2:$C$35,MATCH(AJ$1,'Conversion Range'!$A$2:$A$35,0)))),3)) -> 7.821
A7: ='Legend Attributes'!A7 -> Neymar | B7: ='Legend Attributes'!B7 -> W | C7: =IF('Legend Attributes'!C7=0,0,ROUND(IF(INDEX('Conversion Range'!$E$2:$E$35,MATCH(C$1,'Conversion Range'!$A$2:$A$35,0))=1,INDEX('Conversion Range'!$D$2:$D$35,MATCH(C$1,'Conversion Range'!$A$2:$A$35,0))-(('Legend Attributes'!C7-1)/19)*(INDEX('Conversion Range'!$D$2:$D$35,MATCH(C$1,'Conversion Range'!$A$2:$A$35,0))-INDEX('Conversion Range'!$C$2:$C$35,MATCH(C$1,'Conversion Range'!$A$2:$A$35,0))),INDEX('Conversion Range'!$C$2:$C$35,MATCH(C$1,'Conversion Range'!$A$2:$A$35,0))+(('Legend Attributes'!C7-1)/19)*(INDEX('Conversion Range'!$D$2:$D$35,MATCH(C$1,'Conversion Range'!$A$2:$A$35,0))-INDEX('Conversion Range'!$C$2:$C$35,MATCH(C$1,'Conversion Range'!$A$2:$A$35,0)))),3)) -> 0.632 | D7: =IF('Legend Attributes'!D7=0,0,ROUND(IF(INDEX('Conversion Range'!$E$2:$E$35,MATCH(D$1,'Conversion Range'!$A$2:$A$35,0))=1,INDEX('Conversion Range'!$D$2:$D$35,MATCH(D$1,'Conversion Range'!$A$2:$A$35,0))-(('Legend Attributes'!D7-1)/19)*(INDEX('Conversion Range'!$D$2:$D$35,MATCH(D$1,'Conversion Range'!$A$2:$A$35,0))-INDEX('Conversion Range'!$C$2:$C$35,MATCH(D$1,'Conversion Range'!$A$2:$A$35,0))),INDEX('Conversion Range'!$C$2:$C$35,MATCH(D$1,'Conversion Range'!$A$2:$A$35,0))+(('Legend Attributes'!D7-1)/19)*(INDEX('Conversion Range'!$D$2:$D$35,MATCH(D$1,'Conversion Range'!$A$2:$A$35,0))-INDEX('Conversion Range'!$C$2:$C$35,MATCH(D$1,'Conversion Range'!$A$2:$A$35,0)))),3)) -> 0.558 | E7: =IF('Legend Attributes'!E7=0,0,ROUND(IF(INDEX('Conversion Range'!$E$2:$E$35,MATCH(E$1,'Conversion Range'!$A$2:$A$35,0))=1,INDEX('Conversion Range'!$D$2:$D$35,MATCH(E$1,'Conversion Range'!$A$2:$A$35,0))-(('Legend Attributes'!E7-1)/19)*(INDEX('Conversion Range'!$D$2:$D$35,MATCH(E$1,'Conversion Range'!$A$2:$A$35,0))-INDEX('Conversion Range'!$C$2:$C$35,MATCH(E$1,'Conversion Range'!$A$2:$A$35,0))),INDEX('Conversion Range'!$C$2:$C$35,MATCH(E$1,'Conversion Range'!$A$2:$A$35,0))+(('Legend Attributes'!E7-1)/19)*(INDEX('Conversion Range'!$D$2:$D$35,MATCH(E$1,'Conversion Range'!$A$2:$A$35,0))-INDEX('Conversion Range'!$C$2:$C$35,MATCH(E$1,'Conversion Range'!$A$2:$A$35,0)))),3)) -> 0.408 | F7: =IF('Legend Attributes'!F7=0,0,ROUND(IF(INDEX('Conversion Range'!$E$2:$E$35,MATCH(F$1,'Conversion Range'!$A$2:$A$35,0))=1,INDEX('Conversion Range'!$D$2:$D$35,MATCH(F$1,'Conversion Range'!$A$2:$A$35,0))-(('Legend Attributes'!F7-1)/19)*(INDEX('Conversion Range'!$D$2:$D$35,MATCH(F$1,'Conversion Range'!$A$2:$A$35,0))-INDEX('Conversion Range'!$C$2:$C$35,MATCH(F$1,'Conversion Range'!$A$2:$A$35,0))),INDEX('Conversion Range'!$C$2:$C$35,MATCH(F$1,'Conversion Range'!$A$2:$A$35,0))+(('Legend Attributes'!F7-1)/19)*(INDEX('Conversion Range'!$D$2:$D$35,MATCH(F$1,'Conversion Range'!$A$2:$A$35,0))-INDEX('Conversion Range'!$C$2:$C$35,MATCH(F$1,'Conversion Range'!$A$2:$A$35,0)))),3)) -> 2.784 | G7: =IF('Legend Attributes'!G7=0,0,ROUND(IF(INDEX('Conversion Range'!$E$2:$E$35,MATCH(G$1,'Conversion Range'!$A$2:$A$35,0))=1,INDEX('Conversion Range'!$D$2:$D$35,MATCH(G$1,'Conversion Range'!$A$2:$A$35,0))-(('Legend Attributes'!G7-1)/19)*(INDEX('Conversion Range'!$D$2:$D$35,MATCH(G$1,'Conversion Range'!$A$2:$A$35,0))-INDEX('Conversion Range'!$C$2:$C$35,MATCH(G$1,'Conversion Range'!$A$2:$A$35,0))),INDEX('Conversion Range'!$C$2:$C$35,MATCH(G$1,'Conversion Range'!$A$2:$A$35,0))+(('Legend Attributes'!G7-1)/19)*(INDEX('Conversion Range'!$D$2:$D$35,MATCH(G$1,'Conversion Range'!$A$2:$A$35,0))-INDEX('Conversion Range'!$C$2:$C$35,MATCH(G$1,'Conversion Range'!$A$2:$A$35,0)))),3)) -> 1.482 | H7: =IF('Legend Attributes'!H7=0,0,ROUND(IF(INDEX('Conversion Range'!$E$2:$E$35,MATCH(H$1,'Conversion Range'!$A$2:$A$35,0))=1,INDEX('Conversion Range'!$D$2:$D$35,MATCH(H$1,'Conversion Range'!$A$2:$A$35,0))-(('Legend Attributes'!H7-1)/19)*(INDEX('Conversion Range'!$D$2:$D$35,MATCH(H$1,'Conversion Range'!$A$2:$A$35,0))-INDEX('Conversion Range'!$C$2:$C$35,MATCH(H$1,'Conversion Range'!$A$2:$A$35,0))),INDEX('Conversion Range'!$C$2:$C$35,MATCH(H$1,'Conversion Range'!$A$2:$A$35,0))+(('Legend Attributes'!H7-1)/19)*(INDEX('Conversion Range'!$D$2:$D$35,MATCH(H$1,'Conversion Range'!$A$2:$A$35,0))-INDEX('Conversion Range'!$C$2:$C$35,MATCH(H$1,'Conversion Range'!$A$2:$A$35,0)))),3)) -> 0.737 | I7: =IF('Legend Attributes'!I7=0,0,ROUND(IF(INDEX('Conversion Range'!$E$2:$E$35,MATCH(I$1,'Conversion Range'!$A$2:$A$35,0))=1,INDEX('Conversion Range'!$D$2:$D$35,MATCH(I$1,'Conversion Range'!$A$2:$A$35,0))-(('Legend Attributes'!I7-1)/19)*(INDEX('Conversion Range'!$D$2:$D$35,MATCH(I$1,'Conversion Range'!$A$2:$A$35,0))-INDEX('Conversion Range'!$C$2:$C$35,MATCH(I$1,'Conversion Range'!$A$2:$A$35,0))),INDEX('Conversion Range'!$C$2:$C$35,MATCH(I$1,'Conversion Range'!$A$2:$A$35,0))+(('Legend Attributes'!I7-1)/19)*(INDEX('Conversion Range'!$D$2:$D$35,MATCH(I$1,'Conversion Range'!$A$2:$A$35,0))-INDEX('Conversion Range'!$C$2:$C$35,MATCH(I$1,'Conversion Range'!$A$2:$A$35,0)))),3)) -> 1.811 | J7: =IF('Legend Attributes'!J7=0,0,ROUND(IF(INDEX('Conversion Range'!$E$2:$E$35,MATCH(J$1,'Conversion Range'!$A$2:$A$35,0))=1,INDEX('Conversion Range'!$D$2:$D$35,MATCH(J$1,'Conversion Range'!$A$2:$A$35,0))-(('Legend Attributes'!J7-1)/19)*(INDEX('Conversion Range'!$D$2:$D$35,MATCH(J$1,'Conversion Range'!$A$2:$A$35,0))-INDEX('Conversion Range'!$C$2:$C$35,MATCH(J$1,'Conversion Range'!$A$2:$A$35,0))),INDEX('Conversion Range'!$C$2:$C$35,MATCH(J$1,'Conversion Range'!$A$2:$A$35,0))+(('Legend Attributes'!J7-1)/19)*(INDEX('Conversion Range'!$D$2:$D$35,MATCH(J$1,'Conversion Range'!$A$2:$A$35,0))-INDEX('Conversion Range'!$C$2:$C$35,MATCH(J$1,'Conversion Range'!$A$2:$A$35,0)))),3)) -> 0.689 | ... AJ7: =IF('Legend Attributes'!AJ7=0,0,ROUND(IF(INDEX('Conversion Range'!$E$2:$E$35,MATCH(AJ$1,'Conversion Range'!$A$2:$A$35,0))=1,INDEX('Conversion Range'!$D$2:$D$35,MATCH(AJ$1,'Conversion Range'!$A$2:$A$35,0))-(('Legend Attributes'!AJ7-1)/19)*(INDEX('Conversion Range'!$D$2:$D$35,MATCH(AJ$1,'Conversion Range'!$A$2:$A$35,0))-INDEX('Conversion Range'!$C$2:$C$35,MATCH(AJ$1,'Conversion Range'!$A$2:$A$35,0))),INDEX('Conversion Range'!$C$2:$C$35,MATCH(AJ$1,'Conversion Range'!$A$2:$A$35,0))+(('Legend Attributes'!AJ7-1)/19)*(INDEX('Conversion Range'!$D$2:$D$35,MATCH(AJ$1,'Conversion Range'!$A$2:$A$35,0))-INDEX('Conversion Range'!$C$2:$C$35,MATCH(AJ$1,'Conversion Range'!$A$2:$A$35,0)))),3)) -> 8.011
A8: ='Legend Attributes'!A8 -> Gareth Bale | B8: ='Legend Attributes'!B8 -> W | C8: =IF('Legend Attributes'!C8=0,0,ROUND(IF(INDEX('Conversion Range'!$E$2:$E$35,MATCH(C$1,'Conversion Range'!$A$2:$A$35,0))=1,INDEX('Conversion Range'!$D$2:$D$35,MATCH(C$1,'Conversion Range'!$A$2:$A$35,0))-(('Legend Attributes'!C8-1)/19)*(INDEX('Conversion Range'!$D$2:$D$35,MATCH(C$1,'Conversion Range'!$A$2:$A$35,0))-INDEX('Conversion Range'!$C$2:$C$35,MATCH(C$1,'Conversion Range'!$A$2:$A$35,0))),INDEX('Conversion Range'!$C$2:$C$35,MATCH(C$1,'Conversion Range'!$A$2:$A$35,0))+(('Legend Attributes'!C8-1)/19)*(INDEX('Conversion Range'!$D$2:$D$35,MATCH(C$1,'Conversion Range'!$A$2:$A$35,0))-INDEX('Conversion Range'!$C$2:$C$35,MATCH(C$1,'Conversion Range'!$A$2:$A$35,0)))),3)) -> 0.675 | D8: =IF('Legend Attributes'!D8=0,0,ROUND(IF(INDEX('Conversion Range'!$E$2:$E$35,MATCH(D$1,'Conversion Range'!$A$2:$A$35,0))=1,INDEX('Conversion Range'!$D$2:$D$35,MATCH(D$1,'Conversion Range'!$A$2:$A$35,0))-(('Legend Attributes'!D8-1)/19)*(INDEX('Conversion Range'!$D$2:$D$35,MATCH(D$1,'Conversion Range'!$A$2:$A$35,0))-INDEX('Conversion Range'!$C$2:$C$35,MATCH(D$1,'Conversion Range'!$A$2:$A$35,0))),INDEX('Conversion Range'!$C$2:$C$35,MATCH(D$1,'Conversion Range'!$A$2:$A$35,0))+(('Legend Attributes'!D8-1)/19)*(INDEX('Conversion Range'!$D$2:$D$35,MATCH(D$1,'Conversion Range'!$A$2:$A$35,0))-INDEX('Conversion Range'!$C$2:$C$35,MATCH(D$1,'Conversion Range'!$A$2:$A$35,0)))),3)) -> 0.596 | E8: =IF('Legend Attributes'!E8=0,0,ROUND(IF(INDEX('Conversion Range'!$E$2:$E$35,MATCH(E$1,'Conversion Range'!$A$2:$A$35,0))=1,INDEX('Conversion Range'!$D$2:$D$35,MATCH(E$1,'Conversion Range'!$A$2:$A$35,0))-(('Legend Attributes'!E8-1)/19)*(INDEX('Conversion Range'!$D$2:$D$35,MATCH(E$1,'Conversion Range'!$A$2:$A$35,0))-INDEX('Conversion Range'!$C$2:$C$35,MATCH(E$1,'Conversion Range'!$A$2:$A$35,0))),INDEX('Conversion Range'!$C$2:$C$35,MATCH(E$1,'Conversion Range'!$A$2:$A$35,0))+(('Legend Attributes'!E8-1)/19)*(INDEX('Conversion Range'!$D$2:$D$35,MATCH(E$1,'Conversion Range'!$A$2:$A$35,0))-INDEX('Conversion Range'!$C$2:$C$35,MATCH(E$1,'Conversion Range'!$A$2:$A$35,0)))),3)) -> 0.266 | F8: =IF('Legend Attributes'!F8=0,0,ROUND(IF(INDEX('Conversion Range'!$E$2:$E$35,MATCH(F$1,'Conversion Range'!$A$2:$A$35,0))=1,INDEX('Conversion Range'!$D$2:$D$35,MATCH(F$1,'Conversion Range'!$A$2:$A$35,0))-(('Legend Attributes'!F8-1)/19)*(INDEX('Conversion Range'!$D$2:$D$35,MATCH(F$1,'Conversion Range'!$A$2:$A$35,0))-INDEX('Conversion Range'!$C$2:$C$35,MATCH(F$1,'Conversion Range'!$A$2:$A$35,0))),INDEX('Conversion Range'!$C$2:$C$35,MATCH(F$1,'Conversion Range'!$A$2:$A$35,0))+(('Legend Attributes'!F8-1)/19)*(INDEX('Conversion Range'!$D$2:$D$35,MATCH(F$1,'Conversion Range'!$A$2:$A$35,0))-INDEX('Conversion Range'!$C$2:$C$35,MATCH(F$1,'Conversion Range'!$A$2:$A$35,0)))),3)) -> 3.189 | G8: =IF('Legend Attributes'!G8=0,0,ROUND(IF(INDEX('Conversion Range'!$E$2:$E$35,MATCH(G$1,'Conversion Range'!$A$2:$A$35,0))=1,INDEX('Conversion Range'!$D$2:$D$35,MATCH(G$1,'Conversion Range'!$A$2:$A$35,0))-(('Legend Attributes'!G8-1)/19)*(INDEX('Conversion Range'!$D$2:$D$35,MATCH(G$1,'Conversion Range'!$A$2:$A$35,0))-INDEX('Conversion Range'!$C$2:$C$35,MATCH(G$1,'Conversion Range'!$A$2:$A$35,0))),INDEX('Conversion Range'!$C$2:$C$35,MATCH(G$1,'Conversion Range'!$A$2:$A$35,0))+(('Legend Attributes'!G8-1)/19)*(INDEX('Conversion Range'!$D$2:$D$35,MATCH(G$1,'Conversion Range'!$A$2:$A$35,0))-INDEX('Conversion Range'!$C$2:$C$35,MATCH(G$1,'Conversion Range'!$A$2:$A$35,0)))),3)) -> 1.716 | H8: =IF('Legend Attributes'!H8=0,0,ROUND(IF(INDEX('Conversion Range'!$E$2:$E$35,MATCH(H$1,'Conversion Range'!$A$2:$A$35,0))=1,INDEX('Conversion Range'!$D$2:$D$35,MATCH(H$1,'Conversion Range'!$A$2:$A$35,0))-(('Legend Attributes'!H8-1)/19)*(INDEX('Conversion Range'!$D$2:$D$35,MATCH(H$1,'Conversion Range'!$A$2:$A$35,0))-INDEX('Conversion Range'!$C$2:$C$35,MATCH(H$1,'Conversion Range'!$A$2:$A$35,0))),INDEX('Conversion Range'!$C$2:$C$35,MATCH(H$1,'Conversion Range'!$A$2:$A$35,0))+(('Legend Attributes'!H8-1)/19)*(INDEX('Conversion Range'!$D$2:$D$35,MATCH(H$1,'Conversion Range'!$A$2:$A$35,0))-INDEX('Conversion Range'!$C$2:$C$35,MATCH(H$1,'Conversion Range'!$A$2:$A$35,0)))),3)) -> 0.842 | I8: =IF('Legend Attributes'!I8=0,0,ROUND(IF(INDEX('Conversion Range'!$E$2:$E$35,MATCH(I$1,'Conversion Range'!$A$2:$A$35,0))=1,INDEX('Conversion Range'!$D$2:$D$35,MATCH(I$1,'Conversion Range'!$A$2:$A$35,0))-(('Legend Attributes'!I8-1)/19)*(INDEX('Conversion Range'!$D$2:$D$35,MATCH(I$1,'Conversion Range'!$A$2:$A$35,0))-INDEX('Conversion Range'!$C$2:$C$35,MATCH(I$1,'Conversion Range'!$A$2:$A$35,0))),INDEX('Conversion Range'!$C$2:$C$35,MATCH(I$1,'Conversion Range'!$A$2:$A$35,0))+(('Legend Attributes'!I8-1)/19)*(INDEX('Conversion Range'!$D$2:$D$35,MATCH(I$1,'Conversion Range'!$A$2:$A$35,0))-INDEX('Conversion Range'!$C$2:$C$35,MATCH(I$1,'Conversion Range'!$A$2:$A$35,0)))),3)) -> 1.021 | J8: =IF('Legend Attributes'!J8=0,0,ROUND(IF(INDEX('Conversion Range'!$E$2:$E$35,MATCH(J$1,'Conversion Range'!$A$2:$A$35,0))=1,INDEX('Conversion Range'!$D$2:$D$35,MATCH(J$1,'Conversion Range'!$A$2:$A$35,0))-(('Legend Attributes'!J8-1)/19)*(INDEX('Conversion Range'!$D$2:$D$35,MATCH(J$1,'Conversion Range'!$A$2:$A$35,0))-INDEX('Conversion Range'!$C$2:$C$35,MATCH(J$1,'Conversion Range'!$A$2:$A$35,0))),INDEX('Conversion Range'!$C$2:$C$35,MATCH(J$1,'Conversion Range'!$A$2:$A$35,0))+(('Legend Attributes'!J8-1)/19)*(INDEX('Conversion Range'!$D$2:$D$35,MATCH(J$1,'Conversion Range'!$A$2:$A$35,0))-INDEX('Conversion Range'!$C$2:$C$35,MATCH(J$1,'Conversion Range'!$A$2:$A$35,0)))),3)) -> 0.853 | ... AJ8: =IF('Legend Attributes'!AJ8=0,0,ROUND(IF(INDEX('Conversion Range'!$E$2:$E$35,MATCH(AJ$1,'Conversion Range'!$A$2:$A$35,0))=1,INDEX('Conversion Range'!$D$2:$D$35,MATCH(AJ$1,'Conversion Range'!$A$2:$A$35,0))-(('Legend Attributes'!AJ8-1)/19)*(INDEX('Conversion Range'!$D$2:$D$35,MATCH(AJ$1,'Conversion Range'!$A$2:$A$35,0))-INDEX('Conversion Range'!$C$2:$C$35,MATCH(AJ$1,'Conversion Range'!$A$2:$A$35,0))),INDEX('Conversion Range'!$C$2:$C$35,MATCH(AJ$1,'Conversion Range'!$A$2:$A$35,0))+(('Legend Attributes'!AJ8-1)/19)*(INDEX('Conversion Range'!$D$2:$D$35,MATCH(AJ$1,'Conversion Range'!$A$2:$A$35,0))-INDEX('Conversion Range'!$C$2:$C$35,MATCH(AJ$1,'Conversion Range'!$A$2:$A$35,0)))),3)) -> 7.821
